{
 "cells": [
  {
   "cell_type": "code",
   "execution_count": null,
   "source": [
    "\r\n",
    "# connection au WS\r\n",
    "from azureml.core import Workspace\r\n",
    "ws = Workspace.from_config()\r\n",
    "ws.get_details()\r\n",
    "\r\n",
    "# Execution du script en tant qu'experience\r\n",
    "from azureml.core import Experiment, ScriptRunConfig, Environment\r\n",
    "from azureml.core.conda_dependencies import CondaDependencies\r\n",
    "\r\n",
    "# Create a Python environment for the experiment\r\n",
    "sklearn_env = Environment(\"sklearn-env\")\r\n",
    "\r\n",
    "# Ensure the required packages are installed\r\n",
    "packages = CondaDependencies.create(conda_packages=['scikit-learn','pip'],\r\n",
    "                                    pip_packages=['azureml-defaults'])\r\n",
    "sklearn_env.python.conda_dependencies = packages\r\n",
    "\r\n",
    "# Create a script config + target compute ressource\r\n",
    "script_config = ScriptRunConfig(source_directory=\".\",\r\n",
    "                                script='training_script.py',\r\n",
    "                                compute_target = 'jcharley1',\r\n",
    "                                environment=sklearn_env) \r\n",
    "\r\n",
    "# Submit the experiment\r\n",
    "experiment = Experiment(workspace=ws, name='test4')\r\n",
    "run = experiment.submit(config=script_config)\r\n",
    "run.wait_for_completion()\r\n"
   ],
   "outputs": [],
   "metadata": {}
  },
  {
   "cell_type": "code",
   "execution_count": null,
   "source": [
    "#Récupération des fichiers de modèle\r\n",
    "# List the files generated by the experiment\r\n",
    "for file in run.get_file_names():\r\n",
    "    print(file)\r\n",
    "\r\n",
    "# Download a named file\r\n",
    "run.download_file(name='output/model.pkl', output_file_path='model.pkl')"
   ],
   "outputs": [],
   "metadata": {}
  },
  {
   "cell_type": "markdown",
   "source": [
    "TRACKING DES MODELES - LOCAL"
   ],
   "metadata": {}
  },
  {
   "cell_type": "code",
   "execution_count": 31,
   "source": [
    "from azureml.core import Model\r\n",
    "model = Model.register(workspace=ws,\r\n",
    "                       model_name='rf',\r\n",
    "                       model_path='output/model.pkl', # local path\r\n",
    "                       description='rf test1',\r\n",
    "                       tags={'data-format': 'CSV'},\r\n",
    "                       model_framework=Model.Framework.SCIKITLEARN,\r\n",
    "                       model_framework_version='0.20.3')"
   ],
   "outputs": [
    {
     "output_type": "stream",
     "name": "stdout",
     "text": [
      "Registering model rf\n"
     ]
    }
   ],
   "metadata": {}
  },
  {
   "cell_type": "markdown",
   "source": [
    "Afficher les modèles inscrits"
   ],
   "metadata": {}
  },
  {
   "cell_type": "code",
   "execution_count": 34,
   "source": [
    "from azureml.core import Model\r\n",
    "\r\n",
    "for model in Model.list(ws):\r\n",
    "    \r\n",
    "    # Get model name and auto-generated version\r\n",
    "    print(model.name, 'version:', model.version)"
   ],
   "outputs": [
    {
     "output_type": "stream",
     "name": "stdout",
     "text": [
      "rf version: 1\n"
     ]
    }
   ],
   "metadata": {}
  },
  {
   "cell_type": "markdown",
   "source": [
    "ENREGISTREMENT D'UN JEU DE DONNEES"
   ],
   "metadata": {}
  },
  {
   "cell_type": "code",
   "execution_count": 38,
   "source": [
    "from azureml.core import Dataset\r\n",
    "\r\n",
    "blob_ds = ws.get_default_datastore()\r\n",
    "csv_paths = [(blob_ds, 'data/train_dataset.csv')]\r\n",
    "tab_ds = Dataset.Tabular.from_delimited_files(path=csv_paths)\r\n",
    "tab_ds = tab_ds.register(workspace=ws, name='csv_table')"
   ],
   "outputs": [
    {
     "output_type": "error",
     "ename": "DatasetValidationError",
     "evalue": "DatasetValidationError:\n\tMessage: Cannot load any data from the specified path. Make sure the path is accessible and contains data.\nScriptExecutionException was caused by StreamAccessException.\r\n  StreamAccessException was caused by NotFoundException.\r\n    Found no resources for the input provided: '[REDACTED]'\r\n| session_id=d4bdd079-864e-4910-9c92-17e59921ee89\n\tInnerException None\n\tErrorResponse \n{\n    \"error\": {\n        \"code\": \"UserError\",\n        \"message\": \"Cannot load any data from the specified path. Make sure the path is accessible and contains data.\\nScriptExecutionException was caused by StreamAccessException.\\r\\n  StreamAccessException was caused by NotFoundException.\\r\\n    Found no resources for the input provided: '[REDACTED]'\\r\\n| session_id=d4bdd079-864e-4910-9c92-17e59921ee89\"\n    }\n}",
     "traceback": [
      "\u001b[1;31m---------------------------------------------------------------------------\u001b[0m",
      "\u001b[1;31mExecutionError\u001b[0m                            Traceback (most recent call last)",
      "\u001b[1;32m~\\Anaconda3\\lib\\site-packages\\azureml\\data\\dataset_error_handling.py\u001b[0m in \u001b[0;36m_validate_has_data\u001b[1;34m(dataflow, error_message)\u001b[0m\n\u001b[0;32m     64\u001b[0m     \u001b[1;32mtry\u001b[0m\u001b[1;33m:\u001b[0m\u001b[1;33m\u001b[0m\u001b[1;33m\u001b[0m\u001b[0m\n\u001b[1;32m---> 65\u001b[1;33m         \u001b[0mdataflow\u001b[0m\u001b[1;33m.\u001b[0m\u001b[0mverify_has_data\u001b[0m\u001b[1;33m(\u001b[0m\u001b[1;33m)\u001b[0m\u001b[1;33m\u001b[0m\u001b[1;33m\u001b[0m\u001b[0m\n\u001b[0m\u001b[0;32m     66\u001b[0m     except (dataprep().api.dataflow.DataflowValidationError,\n",
      "\u001b[1;32m~\\Anaconda3\\lib\\site-packages\\azureml\\dataprep\\api\\_loggerfactory.py\u001b[0m in \u001b[0;36mwrapper\u001b[1;34m(*args, **kwargs)\u001b[0m\n\u001b[0;32m    209\u001b[0m                 \u001b[1;32mtry\u001b[0m\u001b[1;33m:\u001b[0m\u001b[1;33m\u001b[0m\u001b[1;33m\u001b[0m\u001b[0m\n\u001b[1;32m--> 210\u001b[1;33m                     \u001b[1;32mreturn\u001b[0m \u001b[0mfunc\u001b[0m\u001b[1;33m(\u001b[0m\u001b[1;33m*\u001b[0m\u001b[0margs\u001b[0m\u001b[1;33m,\u001b[0m \u001b[1;33m**\u001b[0m\u001b[0mkwargs\u001b[0m\u001b[1;33m)\u001b[0m\u001b[1;33m\u001b[0m\u001b[1;33m\u001b[0m\u001b[0m\n\u001b[0m\u001b[0;32m    211\u001b[0m                 \u001b[1;32mexcept\u001b[0m \u001b[0mException\u001b[0m \u001b[1;32mas\u001b[0m \u001b[0me\u001b[0m\u001b[1;33m:\u001b[0m\u001b[1;33m\u001b[0m\u001b[1;33m\u001b[0m\u001b[0m\n",
      "\u001b[1;32m~\\Anaconda3\\lib\\site-packages\\azureml\\dataprep\\api\\dataflow.py\u001b[0m in \u001b[0;36mverify_has_data\u001b[1;34m(self)\u001b[0m\n\u001b[0;32m    872\u001b[0m \u001b[1;33m\u001b[0m\u001b[0m\n\u001b[1;32m--> 873\u001b[1;33m             \u001b[1;32mif\u001b[0m \u001b[0mlen\u001b[0m\u001b[1;33m(\u001b[0m\u001b[0mself\u001b[0m\u001b[1;33m.\u001b[0m\u001b[0mtake\u001b[0m\u001b[1;33m(\u001b[0m\u001b[1;36m1\u001b[0m\u001b[1;33m)\u001b[0m\u001b[1;33m.\u001b[0m\u001b[0m_to_pyrecords\u001b[0m\u001b[1;33m(\u001b[0m\u001b[1;33m)\u001b[0m\u001b[1;33m)\u001b[0m \u001b[1;33m==\u001b[0m \u001b[1;36m0\u001b[0m\u001b[1;33m:\u001b[0m\u001b[1;33m\u001b[0m\u001b[1;33m\u001b[0m\u001b[0m\n\u001b[0m\u001b[0;32m    874\u001b[0m                 \u001b[1;32mraise\u001b[0m \u001b[0mDataflowValidationError\u001b[0m\u001b[1;33m(\u001b[0m\u001b[1;34m\"The Dataflow produced no records.\"\u001b[0m\u001b[1;33m)\u001b[0m\u001b[1;33m\u001b[0m\u001b[1;33m\u001b[0m\u001b[0m\n",
      "\u001b[1;32m~\\Anaconda3\\lib\\site-packages\\azureml\\dataprep\\api\\dataflow.py\u001b[0m in \u001b[0;36m_to_pyrecords\u001b[1;34m(self)\u001b[0m\n\u001b[0;32m    789\u001b[0m                 \u001b[0mself\u001b[0m\u001b[1;33m.\u001b[0m\u001b[0m_raise_if_missing_secrets\u001b[0m\u001b[1;33m(\u001b[0m\u001b[1;33m)\u001b[0m\u001b[1;33m\u001b[0m\u001b[1;33m\u001b[0m\u001b[0m\n\u001b[1;32m--> 790\u001b[1;33m                 self._engine_api.execute_anonymous_activity(\n\u001b[0m\u001b[0;32m    791\u001b[0m                     ExecuteAnonymousActivityMessageArguments(\n",
      "\u001b[1;32m~\\Anaconda3\\lib\\site-packages\\azureml\\dataprep\\api\\_aml_helper.py\u001b[0m in \u001b[0;36mwrapper\u001b[1;34m(op_code, message, cancellation_token)\u001b[0m\n\u001b[0;32m     37\u001b[0m                 \u001b[0mengine_api_func\u001b[0m\u001b[1;33m(\u001b[0m\u001b[1;33m)\u001b[0m\u001b[1;33m.\u001b[0m\u001b[0mupdate_environment_variable\u001b[0m\u001b[1;33m(\u001b[0m\u001b[0mchanged\u001b[0m\u001b[1;33m)\u001b[0m\u001b[1;33m\u001b[0m\u001b[1;33m\u001b[0m\u001b[0m\n\u001b[1;32m---> 38\u001b[1;33m             \u001b[1;32mreturn\u001b[0m \u001b[0msend_message_func\u001b[0m\u001b[1;33m(\u001b[0m\u001b[0mop_code\u001b[0m\u001b[1;33m,\u001b[0m \u001b[0mmessage\u001b[0m\u001b[1;33m,\u001b[0m \u001b[0mcancellation_token\u001b[0m\u001b[1;33m)\u001b[0m\u001b[1;33m\u001b[0m\u001b[1;33m\u001b[0m\u001b[0m\n\u001b[0m\u001b[0;32m     39\u001b[0m \u001b[1;33m\u001b[0m\u001b[0m\n",
      "\u001b[1;32m~\\Anaconda3\\lib\\site-packages\\azureml\\dataprep\\api\\engineapi\\api.py\u001b[0m in \u001b[0;36mexecute_anonymous_activity\u001b[1;34m(self, message_args, cancellation_token)\u001b[0m\n\u001b[0;32m    170\u001b[0m     \u001b[1;32mdef\u001b[0m \u001b[0mexecute_anonymous_activity\u001b[0m\u001b[1;33m(\u001b[0m\u001b[0mself\u001b[0m\u001b[1;33m,\u001b[0m \u001b[0mmessage_args\u001b[0m\u001b[1;33m:\u001b[0m \u001b[0mtypedefinitions\u001b[0m\u001b[1;33m.\u001b[0m\u001b[0mExecuteAnonymousActivityMessageArguments\u001b[0m\u001b[1;33m,\u001b[0m \u001b[0mcancellation_token\u001b[0m\u001b[1;33m:\u001b[0m \u001b[0mCancellationToken\u001b[0m \u001b[1;33m=\u001b[0m \u001b[1;32mNone\u001b[0m\u001b[1;33m)\u001b[0m \u001b[1;33m->\u001b[0m \u001b[1;32mNone\u001b[0m\u001b[1;33m:\u001b[0m\u001b[1;33m\u001b[0m\u001b[1;33m\u001b[0m\u001b[0m\n\u001b[1;32m--> 171\u001b[1;33m         \u001b[0mresponse\u001b[0m \u001b[1;33m=\u001b[0m \u001b[0mself\u001b[0m\u001b[1;33m.\u001b[0m\u001b[0m_message_channel\u001b[0m\u001b[1;33m.\u001b[0m\u001b[0msend_message\u001b[0m\u001b[1;33m(\u001b[0m\u001b[1;34m'Engine.ExecuteActivity'\u001b[0m\u001b[1;33m,\u001b[0m \u001b[0mmessage_args\u001b[0m\u001b[1;33m,\u001b[0m \u001b[0mcancellation_token\u001b[0m\u001b[1;33m)\u001b[0m\u001b[1;33m\u001b[0m\u001b[1;33m\u001b[0m\u001b[0m\n\u001b[0m\u001b[0;32m    172\u001b[0m         \u001b[1;32mreturn\u001b[0m \u001b[0mresponse\u001b[0m\u001b[1;33m\u001b[0m\u001b[1;33m\u001b[0m\u001b[0m\n",
      "\u001b[1;32m~\\Anaconda3\\lib\\site-packages\\azureml\\dataprep\\api\\engineapi\\engine.py\u001b[0m in \u001b[0;36msend_message\u001b[1;34m(self, op_code, message, cancellation_token)\u001b[0m\n\u001b[0;32m    290\u001b[0m             \u001b[0mcancel_on_error\u001b[0m\u001b[1;33m(\u001b[0m\u001b[1;33m)\u001b[0m\u001b[1;33m\u001b[0m\u001b[1;33m\u001b[0m\u001b[0m\n\u001b[1;32m--> 291\u001b[1;33m             \u001b[0mraise_engine_error\u001b[0m\u001b[1;33m(\u001b[0m\u001b[0mresponse\u001b[0m\u001b[1;33m[\u001b[0m\u001b[1;34m'error'\u001b[0m\u001b[1;33m]\u001b[0m\u001b[1;33m)\u001b[0m\u001b[1;33m\u001b[0m\u001b[1;33m\u001b[0m\u001b[0m\n\u001b[0m\u001b[0;32m    292\u001b[0m         \u001b[1;32melse\u001b[0m\u001b[1;33m:\u001b[0m\u001b[1;33m\u001b[0m\u001b[1;33m\u001b[0m\u001b[0m\n",
      "\u001b[1;32m~\\Anaconda3\\lib\\site-packages\\azureml\\dataprep\\api\\errorhandlers.py\u001b[0m in \u001b[0;36mraise_engine_error\u001b[1;34m(error_response)\u001b[0m\n\u001b[0;32m      9\u001b[0m     \u001b[1;32mif\u001b[0m \u001b[1;34m'ScriptExecution'\u001b[0m \u001b[1;32min\u001b[0m \u001b[0merror_code\u001b[0m\u001b[1;33m:\u001b[0m\u001b[1;33m\u001b[0m\u001b[1;33m\u001b[0m\u001b[0m\n\u001b[1;32m---> 10\u001b[1;33m         \u001b[1;32mraise\u001b[0m \u001b[0mExecutionError\u001b[0m\u001b[1;33m(\u001b[0m\u001b[0merror_response\u001b[0m\u001b[1;33m)\u001b[0m\u001b[1;33m\u001b[0m\u001b[1;33m\u001b[0m\u001b[0m\n\u001b[0m\u001b[0;32m     11\u001b[0m     \u001b[1;32mif\u001b[0m \u001b[1;34m'Validation'\u001b[0m \u001b[1;32min\u001b[0m \u001b[0merror_code\u001b[0m\u001b[1;33m:\u001b[0m\u001b[1;33m\u001b[0m\u001b[1;33m\u001b[0m\u001b[0m\n",
      "\u001b[1;31mExecutionError\u001b[0m: \nError Code: ScriptExecution.StreamAccess.NotFound\nFailed Step: a53a2941-eaa3-41d9-8484-77e9c0722eef\nError Message: ScriptExecutionException was caused by StreamAccessException.\r\n  StreamAccessException was caused by NotFoundException.\r\n    Found no resources for the input provided: 'https://trainingstoragef39925970.blob.core.windows.net/azureml-blobstore-8f029277-68ff-4d81-be8d-ef78d356536a/data/train_dataset.csv'\r\n| session_id=d4bdd079-864e-4910-9c92-17e59921ee89",
      "\nDuring handling of the above exception, another exception occurred:\n",
      "\u001b[1;31mDatasetValidationError\u001b[0m                    Traceback (most recent call last)",
      "\u001b[1;32m<ipython-input-38-e9cca5be9cca>\u001b[0m in \u001b[0;36m<module>\u001b[1;34m\u001b[0m\n\u001b[0;32m      3\u001b[0m \u001b[0mblob_ds\u001b[0m \u001b[1;33m=\u001b[0m \u001b[0mws\u001b[0m\u001b[1;33m.\u001b[0m\u001b[0mget_default_datastore\u001b[0m\u001b[1;33m(\u001b[0m\u001b[1;33m)\u001b[0m\u001b[1;33m\u001b[0m\u001b[1;33m\u001b[0m\u001b[0m\n\u001b[0;32m      4\u001b[0m \u001b[0mcsv_paths\u001b[0m \u001b[1;33m=\u001b[0m \u001b[1;33m[\u001b[0m\u001b[1;33m(\u001b[0m\u001b[0mblob_ds\u001b[0m\u001b[1;33m,\u001b[0m \u001b[1;34m'data/train_dataset.csv'\u001b[0m\u001b[1;33m)\u001b[0m\u001b[1;33m]\u001b[0m\u001b[1;33m\u001b[0m\u001b[1;33m\u001b[0m\u001b[0m\n\u001b[1;32m----> 5\u001b[1;33m \u001b[0mtab_ds\u001b[0m \u001b[1;33m=\u001b[0m \u001b[0mDataset\u001b[0m\u001b[1;33m.\u001b[0m\u001b[0mTabular\u001b[0m\u001b[1;33m.\u001b[0m\u001b[0mfrom_delimited_files\u001b[0m\u001b[1;33m(\u001b[0m\u001b[0mpath\u001b[0m\u001b[1;33m=\u001b[0m\u001b[0mcsv_paths\u001b[0m\u001b[1;33m)\u001b[0m\u001b[1;33m\u001b[0m\u001b[1;33m\u001b[0m\u001b[0m\n\u001b[0m\u001b[0;32m      6\u001b[0m \u001b[0mtab_ds\u001b[0m \u001b[1;33m=\u001b[0m \u001b[0mtab_ds\u001b[0m\u001b[1;33m.\u001b[0m\u001b[0mregister\u001b[0m\u001b[1;33m(\u001b[0m\u001b[0mworkspace\u001b[0m\u001b[1;33m=\u001b[0m\u001b[0mws\u001b[0m\u001b[1;33m,\u001b[0m \u001b[0mname\u001b[0m\u001b[1;33m=\u001b[0m\u001b[1;34m'csv_table'\u001b[0m\u001b[1;33m)\u001b[0m\u001b[1;33m\u001b[0m\u001b[1;33m\u001b[0m\u001b[0m\n",
      "\u001b[1;32m~\\Anaconda3\\lib\\site-packages\\azureml\\data\\_loggerfactory.py\u001b[0m in \u001b[0;36mwrapper\u001b[1;34m(*args, **kwargs)\u001b[0m\n\u001b[0;32m    127\u001b[0m             \u001b[1;32mwith\u001b[0m \u001b[0m_LoggerFactory\u001b[0m\u001b[1;33m.\u001b[0m\u001b[0mtrack_activity\u001b[0m\u001b[1;33m(\u001b[0m\u001b[0mlogger\u001b[0m\u001b[1;33m,\u001b[0m \u001b[0mfunc\u001b[0m\u001b[1;33m.\u001b[0m\u001b[0m__name__\u001b[0m\u001b[1;33m,\u001b[0m \u001b[0mactivity_type\u001b[0m\u001b[1;33m,\u001b[0m \u001b[0mcustom_dimensions\u001b[0m\u001b[1;33m)\u001b[0m \u001b[1;32mas\u001b[0m \u001b[0mal\u001b[0m\u001b[1;33m:\u001b[0m\u001b[1;33m\u001b[0m\u001b[1;33m\u001b[0m\u001b[0m\n\u001b[0;32m    128\u001b[0m                 \u001b[1;32mtry\u001b[0m\u001b[1;33m:\u001b[0m\u001b[1;33m\u001b[0m\u001b[1;33m\u001b[0m\u001b[0m\n\u001b[1;32m--> 129\u001b[1;33m                     \u001b[1;32mreturn\u001b[0m \u001b[0mfunc\u001b[0m\u001b[1;33m(\u001b[0m\u001b[1;33m*\u001b[0m\u001b[0margs\u001b[0m\u001b[1;33m,\u001b[0m \u001b[1;33m**\u001b[0m\u001b[0mkwargs\u001b[0m\u001b[1;33m)\u001b[0m\u001b[1;33m\u001b[0m\u001b[1;33m\u001b[0m\u001b[0m\n\u001b[0m\u001b[0;32m    130\u001b[0m                 \u001b[1;32mexcept\u001b[0m \u001b[0mException\u001b[0m \u001b[1;32mas\u001b[0m \u001b[0me\u001b[0m\u001b[1;33m:\u001b[0m\u001b[1;33m\u001b[0m\u001b[1;33m\u001b[0m\u001b[0m\n\u001b[0;32m    131\u001b[0m                     \u001b[1;32mif\u001b[0m \u001b[0mhasattr\u001b[0m\u001b[1;33m(\u001b[0m\u001b[0mal\u001b[0m\u001b[1;33m,\u001b[0m \u001b[1;34m'activity_info'\u001b[0m\u001b[1;33m)\u001b[0m \u001b[1;32mand\u001b[0m \u001b[0mhasattr\u001b[0m\u001b[1;33m(\u001b[0m\u001b[0me\u001b[0m\u001b[1;33m,\u001b[0m \u001b[1;34m'error_code'\u001b[0m\u001b[1;33m)\u001b[0m\u001b[1;33m:\u001b[0m\u001b[1;33m\u001b[0m\u001b[1;33m\u001b[0m\u001b[0m\n",
      "\u001b[1;32m~\\Anaconda3\\lib\\site-packages\\azureml\\data\\dataset_factory.py\u001b[0m in \u001b[0;36mfrom_delimited_files\u001b[1;34m(path, validate, include_path, infer_column_types, set_column_types, separator, header, partition_format, support_multi_line, empty_as_string, encoding)\u001b[0m\n\u001b[0;32m    360\u001b[0m                                            encoding=encoding)\n\u001b[0;32m    361\u001b[0m \u001b[1;33m\u001b[0m\u001b[0m\n\u001b[1;32m--> 362\u001b[1;33m         dataflow = _transform_and_validate(\n\u001b[0m\u001b[0;32m    363\u001b[0m             \u001b[0mdataflow\u001b[0m\u001b[1;33m,\u001b[0m \u001b[0mpartition_format\u001b[0m\u001b[1;33m,\u001b[0m \u001b[0minclude_path\u001b[0m\u001b[1;33m,\u001b[0m\u001b[1;33m\u001b[0m\u001b[1;33m\u001b[0m\u001b[0m\n\u001b[0;32m    364\u001b[0m             validate or infer_column_types or _is_inference_required(set_column_types))\n",
      "\u001b[1;32m~\\Anaconda3\\lib\\site-packages\\azureml\\data\\dataset_factory.py\u001b[0m in \u001b[0;36m_transform_and_validate\u001b[1;34m(dataflow, partition_format, include_path, validate)\u001b[0m\n\u001b[0;32m   1142\u001b[0m         \u001b[0mdataflow\u001b[0m \u001b[1;33m=\u001b[0m \u001b[0mdataflow\u001b[0m\u001b[1;33m.\u001b[0m\u001b[0mdrop_columns\u001b[0m\u001b[1;33m(\u001b[0m\u001b[1;34m'Path'\u001b[0m\u001b[1;33m)\u001b[0m\u001b[1;33m\u001b[0m\u001b[1;33m\u001b[0m\u001b[0m\n\u001b[0;32m   1143\u001b[0m     \u001b[1;32mif\u001b[0m \u001b[0mvalidate\u001b[0m\u001b[1;33m:\u001b[0m\u001b[1;33m\u001b[0m\u001b[1;33m\u001b[0m\u001b[0m\n\u001b[1;32m-> 1144\u001b[1;33m         _validate_has_data(dataflow, 'Cannot load any data from the specified path. '\n\u001b[0m\u001b[0;32m   1145\u001b[0m                                      'Make sure the path is accessible and contains data.')\n\u001b[0;32m   1146\u001b[0m     \u001b[1;32mreturn\u001b[0m \u001b[0mdataflow\u001b[0m\u001b[1;33m\u001b[0m\u001b[1;33m\u001b[0m\u001b[0m\n",
      "\u001b[1;32m~\\Anaconda3\\lib\\site-packages\\azureml\\data\\dataset_error_handling.py\u001b[0m in \u001b[0;36m_validate_has_data\u001b[1;34m(dataflow, error_message)\u001b[0m\n\u001b[0;32m     66\u001b[0m     except (dataprep().api.dataflow.DataflowValidationError,\n\u001b[0;32m     67\u001b[0m             dataprep().api.errorhandlers.ExecutionError) as e:\n\u001b[1;32m---> 68\u001b[1;33m         \u001b[1;32mraise\u001b[0m \u001b[0mDatasetValidationError\u001b[0m\u001b[1;33m(\u001b[0m\u001b[0merror_message\u001b[0m \u001b[1;33m+\u001b[0m \u001b[1;34m'\\n'\u001b[0m \u001b[1;33m+\u001b[0m \u001b[0me\u001b[0m\u001b[1;33m.\u001b[0m\u001b[0mcompliant_message\u001b[0m\u001b[1;33m,\u001b[0m \u001b[0mexception\u001b[0m\u001b[1;33m=\u001b[0m\u001b[0me\u001b[0m\u001b[1;33m)\u001b[0m\u001b[1;33m\u001b[0m\u001b[1;33m\u001b[0m\u001b[0m\n\u001b[0m\u001b[0;32m     69\u001b[0m \u001b[1;33m\u001b[0m\u001b[0m\n\u001b[0;32m     70\u001b[0m \u001b[1;33m\u001b[0m\u001b[0m\n",
      "\u001b[1;31mDatasetValidationError\u001b[0m: DatasetValidationError:\n\tMessage: Cannot load any data from the specified path. Make sure the path is accessible and contains data.\nScriptExecutionException was caused by StreamAccessException.\r\n  StreamAccessException was caused by NotFoundException.\r\n    Found no resources for the input provided: '[REDACTED]'\r\n| session_id=d4bdd079-864e-4910-9c92-17e59921ee89\n\tInnerException None\n\tErrorResponse \n{\n    \"error\": {\n        \"code\": \"UserError\",\n        \"message\": \"Cannot load any data from the specified path. Make sure the path is accessible and contains data.\\nScriptExecutionException was caused by StreamAccessException.\\r\\n  StreamAccessException was caused by NotFoundException.\\r\\n    Found no resources for the input provided: '[REDACTED]'\\r\\n| session_id=d4bdd079-864e-4910-9c92-17e59921ee89\"\n    }\n}"
     ]
    }
   ],
   "metadata": {}
  },
  {
   "cell_type": "code",
   "execution_count": null,
   "source": [],
   "outputs": [],
   "metadata": {}
  },
  {
   "cell_type": "code",
   "execution_count": null,
   "source": [],
   "outputs": [],
   "metadata": {}
  },
  {
   "cell_type": "code",
   "execution_count": null,
   "source": [],
   "outputs": [],
   "metadata": {}
  }
 ],
 "metadata": {
  "orig_nbformat": 4,
  "language_info": {
   "name": "python",
   "version": "3.8.8",
   "mimetype": "text/x-python",
   "codemirror_mode": {
    "name": "ipython",
    "version": 3
   },
   "pygments_lexer": "ipython3",
   "nbconvert_exporter": "python",
   "file_extension": ".py"
  },
  "kernelspec": {
   "name": "python3",
   "display_name": "Python 3.8.8 64-bit ('base': conda)"
  },
  "interpreter": {
   "hash": "f4d2fc3f9599656570a986cacd0f8fb633e1f5eb6c0d7edd902095b821fab887"
  }
 },
 "nbformat": 4,
 "nbformat_minor": 2
}