{
 "cells": [
  {
   "cell_type": "code",
   "execution_count": 8,
   "source": [
    "from azureml.data import OutputFileDatasetConfig\r\n",
    "from azureml.pipeline.steps import PythonScriptStep, EstimatorStep\r\n",
    "# connection au WS\r\n",
    "from azureml.core import Workspace\r\n",
    "ws = Workspace.from_config()\r\n",
    "ws.get_details()\r\n",
    "\r\n",
    "# Execution du script en tant qu'experience\r\n",
    "from azureml.core import Experiment, ScriptRunConfig, Environment\r\n",
    "from azureml.core.conda_dependencies import CondaDependencies\r\n",
    "\r\n",
    "# Create a Python environment for the experiment\r\n",
    "sklearn_env = Environment(\"sklearn-env\")\r\n",
    "\r\n",
    "step1 = PythonScriptStep(name = 'data_cleaning',\r\n",
    "                         source_directory = 'scripts',\r\n",
    "                         script_name = 'datacleaning_scipt1.py',\r\n",
    "                         compute_target = 'jcharley1',\r\n",
    "                         runconfig = run_config,\r\n",
    "                         #inputs=[raw_ds.as_named_input('raw_data')],\r\n",
    "                         outputs=[prepped_data],\r\n",
    "                         arguments = ['--folder', prepped_data],\r\n",
    "                         # Disable step reuse\r\n",
    "                         allow_reuse = True)\r\n"
   ],
   "outputs": [
    {
     "output_type": "error",
     "ename": "UserErrorException",
     "evalue": "UserErrorException:\n\tMessage: We could not find config.json in: c:\\ or in its parent directories. Please provide the full path to the config file or ensure that config.json exists in the parent directories.\n\tInnerException None\n\tErrorResponse \n{\n    \"error\": {\n        \"code\": \"UserError\",\n        \"message\": \"We could not find config.json in: c:\\\\ or in its parent directories. Please provide the full path to the config file or ensure that config.json exists in the parent directories.\"\n    }\n}",
     "traceback": [
      "\u001b[1;31m---------------------------------------------------------------------------\u001b[0m",
      "\u001b[1;31mUserErrorException\u001b[0m                        Traceback (most recent call last)",
      "\u001b[1;32m<ipython-input-8-cb0596e77b6d>\u001b[0m in \u001b[0;36m<module>\u001b[1;34m\u001b[0m\n\u001b[0;32m      3\u001b[0m \u001b[1;31m# connection au WS\u001b[0m\u001b[1;33m\u001b[0m\u001b[1;33m\u001b[0m\u001b[1;33m\u001b[0m\u001b[0m\n\u001b[0;32m      4\u001b[0m \u001b[1;32mfrom\u001b[0m \u001b[0mazureml\u001b[0m\u001b[1;33m.\u001b[0m\u001b[0mcore\u001b[0m \u001b[1;32mimport\u001b[0m \u001b[0mWorkspace\u001b[0m\u001b[1;33m\u001b[0m\u001b[1;33m\u001b[0m\u001b[0m\n\u001b[1;32m----> 5\u001b[1;33m \u001b[0mws\u001b[0m \u001b[1;33m=\u001b[0m \u001b[0mWorkspace\u001b[0m\u001b[1;33m.\u001b[0m\u001b[0mfrom_config\u001b[0m\u001b[1;33m(\u001b[0m\u001b[1;33m)\u001b[0m\u001b[1;33m\u001b[0m\u001b[1;33m\u001b[0m\u001b[0m\n\u001b[0m\u001b[0;32m      6\u001b[0m \u001b[0mws\u001b[0m\u001b[1;33m.\u001b[0m\u001b[0mget_details\u001b[0m\u001b[1;33m(\u001b[0m\u001b[1;33m)\u001b[0m\u001b[1;33m\u001b[0m\u001b[1;33m\u001b[0m\u001b[0m\n\u001b[0;32m      7\u001b[0m \u001b[1;33m\u001b[0m\u001b[0m\n",
      "\u001b[1;32m~\\Anaconda3\\lib\\site-packages\\azureml\\core\\workspace.py\u001b[0m in \u001b[0;36mfrom_config\u001b[1;34m(path, auth, _logger, _file_name)\u001b[0m\n\u001b[0;32m    282\u001b[0m \u001b[1;33m\u001b[0m\u001b[0m\n\u001b[0;32m    283\u001b[0m             \u001b[1;32mif\u001b[0m \u001b[1;32mnot\u001b[0m \u001b[0mfound_path\u001b[0m\u001b[1;33m:\u001b[0m\u001b[1;33m\u001b[0m\u001b[1;33m\u001b[0m\u001b[0m\n\u001b[1;32m--> 284\u001b[1;33m                 raise UserErrorException(\n\u001b[0m\u001b[0;32m    285\u001b[0m                     \u001b[1;34m'We could not find config.json in: {} or in its parent directories. '\u001b[0m\u001b[1;33m\u001b[0m\u001b[1;33m\u001b[0m\u001b[0m\n\u001b[0;32m    286\u001b[0m                     \u001b[1;34m'Please provide the full path to the config file or ensure that '\u001b[0m\u001b[1;33m\u001b[0m\u001b[1;33m\u001b[0m\u001b[0m\n",
      "\u001b[1;31mUserErrorException\u001b[0m: UserErrorException:\n\tMessage: We could not find config.json in: c:\\ or in its parent directories. Please provide the full path to the config file or ensure that config.json exists in the parent directories.\n\tInnerException None\n\tErrorResponse \n{\n    \"error\": {\n        \"code\": \"UserError\",\n        \"message\": \"We could not find config.json in: c:\\\\ or in its parent directories. Please provide the full path to the config file or ensure that config.json exists in the parent directories.\"\n    }\n}"
     ]
    }
   ],
   "metadata": {}
  },
  {
   "cell_type": "code",
   "execution_count": null,
   "source": [],
   "outputs": [],
   "metadata": {}
  },
  {
   "cell_type": "code",
   "execution_count": null,
   "source": [],
   "outputs": [],
   "metadata": {}
  },
  {
   "cell_type": "code",
   "execution_count": null,
   "source": [],
   "outputs": [],
   "metadata": {}
  },
  {
   "cell_type": "code",
   "execution_count": null,
   "source": [],
   "outputs": [],
   "metadata": {}
  }
 ],
 "metadata": {
  "orig_nbformat": 4,
  "language_info": {
   "name": "python",
   "version": "3.8.8"
  },
  "kernelspec": {
   "name": "python3",
   "display_name": "Python 3.8.8 64-bit ('base': conda)"
  },
  "interpreter": {
   "hash": "f4d2fc3f9599656570a986cacd0f8fb633e1f5eb6c0d7edd902095b821fab887"
  }
 },
 "nbformat": 4,
 "nbformat_minor": 2
}